# 08 예외처리(exception handling)

## 1. 프로그램 오류

에러의 종류

- 컴파일 에러 - 컴파일 시에 발생하는 에러
- 런타임 에러 - 실행 시에 발생하는 에러
- 논리적 에러 - 실행은 되지만, 의도와 - 다르게 동작하는 것

런타임시 발생할 수 있는 오류

- 에러(error) - 코드로 수습될 수 없는 - 심각한 오류
- 예외(exception) - 코드로 수습 할 수 있는 경미한 오류

## 2. 예외 클래스의 계층구조

- Object
  - Throwable
    - Error
      - OutOfMemoryError
      - ...
    - **Exception**
      - IOException
      - ClassNotFoundException
      - ...
      - **RuntimeException**
        - ArithmeticException
        - ClassCastException
        - NullPointerException
        - ...
        - IndexOutOfBoundsException

> Exception클래스들 - 사용자의 실수와 같은 외적인 요인의 의해 발생하는 예외  
> RuntimeException클래스들 - 프로그래머의 실수로 발생하는 예외

## 3. 예외처리하기 - try-catch문

예외처리

- 정의 - 프로그램 실행 시 발생할 수 있는 예외에 대비한 코드를 작성하는 것
- 목적 - 프로그램의 비정상 종료를 막고, 정상적인 실행상태를 유지하는 것.

```java
try{
    // 예외 발생 가능성이 있는 코드
} catch (Exception1 e1) {
    // Exception1이 발생한 경우, 처리를 위한 코드
} catch (Exception2 e2) {
    // Exception2이 발생한 경우, 처리를 위한 코드
}
```

try-catch 내부에서도 사용가능

```java
try{
    try{

    }catch (Exception e){

    }
}catch (Exception e){
    try{

    }catch (Exception e){   // ERROR, e가 중복 선언됨

    }
}
```

예시

```java
Class ExceptionEx{
    public static void main(String args[]){
        int number = 100;
        int result = 0;

        for(int i = 0; i < 10; ++i){
            try{
                result = number / (int) (Math.random() * 10); // Math.random()에서 0이 나올 수 있음.
                System.out.println(result);
            }catch(ArithmeticException e){
                System.out.print("0");
            }
        }
    }
}
```

## 4. try-catch문에서의 흐름

- try블럭 내에서 예외가 발생한 경우
  1. 발생한 예외와 일치하는 catch블럭이 있는지 확인
  2. 일치하는 catch블럭을 찾게 되면, 그 catch블럭 내의 문장들을 수행하고 전체 try-catch문을 빠져나가서 그 다음 문장을 계속해서 수행한다.
  3. 일치하는 catch블럭을 찾지 못하면, 예외는 처리되지 못한다.
- try블럭 내에서 예외가 발생하지 않은 경우
  1. catch블럭을 거치지 않고 전체 try-catch문을 빠져나가서 수행을 계속

```java
System.out.println(1);
try{
    System.out.println(2);
    System.out.println(0 / 0);  //  Exception 발생.
    System.out.println(3);      // 실행되지 않음.
} catch (ArithmeticException ae){
    System.out.println(4);
} catch (Exception e){
    System.out.println(5);      // 실행되지 않음.
}
System.out.println(6);
```

## 5. 예외의 발생과 catch블럭

- printStackTrace() - 예외발생 당시의 호출스택(Call Stack)에 있었던 메서드의 정보와 예외 메시지를 화면에 출력.
- getMessage() - 발생한 예외클래스의 인스턴스에 저장된 메시지.

```java
try{
    System.out.println(2);
    System.out.println(0 / 0);  //  Exception 발생.
} catch (ArithmeticException ae){
    ae.printStackTrace();                           // java.lang.ArithmeticException: / by zero
    System.out.println("예외 " + ae.getMessage());  // / by zero
}
```

멀티 catch블럭

```java
try{
    // ...
} catch (ExceptionA | ExceptionB e){    // 여러 개의 exception을 한번에 받을 수 있음.
    e.printStackTrace();
}
```

A, B가 조상과 자손 관계이면 조상만 쓴 것과 같으므로 에러 발생.

## 6. 예외 발생시키기

```java
class ExceptionEX{
    public static void main(){
        try{
            // throw new Exception("예외 발생");
            Exception e = new Exception("예외 발생");   // 예외 객체 생성
            throw e;                                    // 예외 발생
        } catch (Exception e){
            e.printStackTrace();
        }
    }
}
```

checked예외

```java
class ExceptionEX{
    public static void main(){
        throw new Exception();  // 컴파일 오류, 예외처리를 해줘야 함.
    }
}
```

unchecked예외

```java
class ExceptionEX{
    public static void main(){
        throw new RundtimeException();  // 컴파일 성공, 실행시 오류
    }
}
```

## 7. 메서드에 예외 선언하기

```java
void method() throws Exception1, ... ExceptionN{

}
```

> 이 메서드를 사용하기 위해서 필요한 예외처리를 쉽게 알 수 있음.  
> 예외를 처리하는 것이 아니라 호출 메서드에게 예외를 떠넘기는 것.

예제

![wait api](images/08%20예외처리_wait_api.png)

InterruptedException을 예외처리해줘야 wait를 쓸 수 있음.

![InterruptedException](images/08%20예외처리_InterruptedException.png)

IllegalMonitorStateException 또한 발생 시키지만 굳이 예외처리 하지 않아도 됨.

![IllegalMonitorStateException](images/08%20예외처리_IllegalMonitorStateException.png)

예외처리 넘기기

```java
class ExceptionEx(){
    public static void main() throws Exception{
        method1();
    }

    static void method1() throws Exception{
        method2();
    }
    static void method2() throws Exception{
        throw new Exception();
    }
}
```

출력화면

```
java.lang.Exception
    at ExceptionEx.method2(ExceptionEx12.java:11)
    at ExceptionEx.method1(ExceptionEx12.java:7)
    at ExceptionEx.main(ExceptionEx12.java:3)
```

에러 메시지의 호출 스택을 보면 method2가 예외를 발생시켰으나, 아무도 처리해주지 않아 main이 비정상 종료됨.

올바른 예외 처리

```java
class ExceptionEx(){
    public static void main(){
        method1();
    }

    static void method1(){
        try{
            throw new Exception();
        }catch (Exception e){
            System.out.println("method에서 예외 처리");
            e.printStackTrace();
        }
    }
}
```

```java
class ExceptionEx(){
    public static void main(){
        try{
            method1();
        }catch (Exception e){
            System.out.println("main에서 에외 처리");
            e.printStackTrace();
        }
    }

    static void method1() throws Exception{
        throw new Exception();
    }
}
```

예제 - 파일 생성

예외가 발생한 메서드에서 직접 처리  
임의의 파일명으로 파일 생성

```java
import java.io.*;

calss ExceptionEx{
    public static void main(String[] args){
        File f = createFile(args[0]);
        System.out.println(f.getName() + " 파일을 생성했습니다.");
    }

    static File createFile(String fileName){
        try{
            if (fileName==null || fileName.equals("")){
                throw new Exception("파일명이 유요하지 않습니다.");
            }
        }catch(Exception e){
            fileName = "제목없음.txt";      // 유요하지 않은 파일명 처리
        }finally{
            File f = new File(fileName);    // file 객체 생성
            createNewFile(f);               // 객체로 파일 생성
            return f;
        }
    }

    static void createNewFile(File f){
        try{
            f.createNewfile();  // 파일 생성
        }catch(Exception e){

        }
    }
}
```

main에서 예외처리  
다시 파일명을 받게 처리

```java
import java.io.*;

calss ExceptionEx{
    public static void main(String[] args){
        try{
            File f = createFile(args[0]);
            System.out.println(f.getName() + " 파일을 생성했습니다.");
        } catch(Exception e){
            System.out.println(e.getName() + " 다시 입력해 주세요");
        }
    }

    static File createFile(String fileName) throws Exception{

        if (fileName==null || fileName.equals("")){
            throw new Exception("파일명이 유요하지 않습니다.");
        }

        fileName = "제목없음.txt";      // 유요하지 않은 파일명 처리

        File f = new File(fileName);    // file 객체 생성
        f.createNewFile();              // 객체로 파일 생성, 따로 예외 처리 필요 없음.
        return f;
    }
}
```

## 8. finally 블럭

```java
try{
    // 예외 가능서 있는 코드
}catch(Exception1 e1){
    // 예외 처리 코드
}finally{
    // 예외 발생 여부와 상관없이 항상 실행되어야 할 코드
}
```

```java
class FinallyTest(){
    public static void main(){
        FinallyTest.method1();
        System.out.println("method1() 수행 후 main 복귀");
    }

    static void method1(){
        try{
            System.out.println("method1() 호출");
            return;
        }catche(Exception e){
            e.printStackTrace();
        }finally{
            System.out.println("method1()의 finally블럭 실행");
        }
    }
}
```

출력

```
method1() 호출
method1()의 finally블럭 실행
method1() 수행 후 main 복귀
```

## 9. 자동 자원 반환 - try-with-resources문

자원을 자동으로 반환하는 구문
JDK 1.7부터 추가됨.
I/O 클래스와 사용할 때 유용

```java
try{
    fis = new FileInputStream("score.dat"); // 예외처리 필요
    dis = new DataInputStream(fis);
} catch (IOException ie) {
    ie.printStackTrace();
} finally {
    try{
        if(dis != null) dis.close();    // close() 또한 예외처리 필요
    } catch (IOException ie) {
        ie.printStackTrace();
    }
}
```

try-with-resources문

```java
try (fis = new FileInputStream("score.dat"); // 자동 close()
    dis = new DataInputStream(fis);){
    // 파일처리구현
} catch (IOException ie) {
    ie.printStackTrace();
}
```

try-with-resources문은 AutoCloseable 인터페이스를 구현한 것만 가능

```java
public interface AutoCloseable {
    void close() throws Exception;
}
```

try-with-resources문에서 close()시 예외가 발생하면?

```java
class TryWithResourceEx(){
    public static void main(){
        // close()만 예외 발생
        try(CloseableResource cr = new CloseableResource()){
            cr.exceptionWork(false);    // 예외 발생 없음.
        } catch (WorkExceptin e) {
            e.printStackTrace();
        } catch (CloseExceptin e) {
            e.printStackTrace();
        }

        // exceptionWork(), close() 모두 예외 발생
        try(CloseableResource cr = new CloseableResource()){
            cr.exceptionWork(true);    // 예외 발생 없음.
        } catch (WorkExceptin e) {
            e.printStackTrace();
        } catch (CloseExceptin e) {
            e.printStackTrace();
        }
    }
}

class CloseableResource implements AutoCloseable{
    public void exceptionWork(boolean exception) throws WorkExcpetion{
        System.out.println("exceptionWork("+exception+")가 호출됨");
        if(exception){
            throw new WorkException("WorkException 발생");
        }
    }

    public void close() throws CloseException{
        System.out.println("close()가 호출됨");
        throw new CloseException("CloseException 발생");
    }
}

class WorkException extends Exception{
    WorkException(String msg){super(msg)}
}
class CloseException extends Exception{
    WorkException(String msg){super(msg)}
}

```

출력화면

```
exceptionWork(false)가 호출됨
close()가 호출됨
CloseException: CloseException 발생
    at CloseableResource.close(TryWithResourceEx.java:33)
    at TryWithResourceEx.main(TryWithResourceEx.java::6)
exceptionWork(true)가 호출됨
close()가 호출됨
WorkException: WorkException 발생
    at CloseableResource.WorkException(TryWithResourceEx.java:33)
    at TryWithResourceEx.main(TryWithResourceEx.java::6)
    Suppressed: CloseException: CloseException 발생
        at CloseableResource.close(TryWithResourceEx.java:33)
        at TryWithResourceEx.main(TryWithResourceEx.java::6)
```

원래는 두 예외가 동시에 발생 할 수 없으나,  
exceptionWork()예외가 발생하고 close()예외가 발생  
close()예외는 억제된(suppressed)로 표현됨.  
기존 try-catch문이면 WorkException은 무시되고, CloseException

## 10. 사용자정의 예외 만들기

> 새로운 예외클래스보다 기존의 예외클래스를 활용하자.

```java
class MyException extends Exception{
    MyException(String msg){    // 문자열을 받는 생성자
        super(msg);             // Exception의 생성자 호출
    }
}
```

- Exception을 상속받아 checked예외로 하기보다,  
  RuntimeException을 상속받아 unchecked예외로 만드는 추세.
- 예전에 필수라고 생각한 예외처리가 (웹, 모방일로) 환경의 변화에따라 필수 예외가 아니게 됨.

## 11. 예외 되던지기(exception re-throwing)

- 예외 되던지기 - 한 개의 예외의 경우에 처리 한후 다시 발생시키는 것.
- 보통 예외가 여러개인 경우, 일부는 메서드 내부에서 일부는 외부에서 처리 할 수 있음.
- 한 예외에 대해 메서드와 호출 한 쪽 양쪽 모두에서 예외처리가 필요한 경우 사용.

```java
class ExceptionEx{
    public static void main(){
        try{
            method1();
        } catch (Exception e) {
            System.out.println("main에서 예외 처리");
        }
    }

    static int method1() throws Exception{
        try{
            throw new Exception();
            return 0;
        } catch (Exception e) {
            System.out.println("method1에서 예외 처리");
            // return 1;    // 리턴 대신 예외가 넘어감.
            throw e;        // 다시 예외를 발생 시킴.
        }
    }
}
```

반환 값이 존재하는 메서드는 catch에서도 return을 해야하나, 예외를 던지면 필요 없음.

## 12. 연결된 예외(chained exception)

- 예외A가 예외B를 발생시키는 것.
- 예외A - 예외B의 원인 예외(cause exception)
- 여러 예외를 하나로 묶어서 처리하기 위함.

InstallException이 SpaceException, MemoryException의 조상이 아니더라도 예외를 묶을 수 있음.

```java
Throwable initCause(Throwable cause)    // 지정한 예외를 원인 예외로 등록
Throwable getCause()                    // 원인 예외를 반환
```

```java
try{
    startInstall();
    copyFiles();
} catch (SpaceException e) {
    InstallException ie = new InstallException("설치중 예외발생");
    ie.initCause(e);            // InstallException의 원인 예외를 SpaceException로 지정.
    throw ie;                   // InstallException을 발생.
} catch (MemoryException me) {
    // ...
}
```

checked예외를 unchecked예외로 바꿀 수 있음.

before

```java
static void startIntall() throws SpaceException, MemoryException{
    if(!enoughSpace()){
        throw new SpaceException("설치할 공간이 부족합니다.");
    }
    if(!enoughMemory()){
        throw new MemoryException("메모리가 부족합니다."));
    }
}
```

after

```java
static void startIntall() throws SpaceException{
    if(!enoughSpace()){
        throw new SpaceException("설치할 공간이 부족합니다.");
    }
    if(!enoughMemory()){
        throw new RuntimeException(new MemoryException("메모리가 부족합니다."));
        // RuntimeException으로 감싸 unchecked예외가 됨.
    }
}
```

예외 전체 소스코드 <https://github.com/castello/javajungsuk3/blob/master/source/ch8/ChainedExceptionEx.java>
